uncaught exception: FOO
	at bar (test/runnable/fail:9)
	at foo (test/runnable/fail:6)
	at main (test/runnable/fail:3)
	at add-first-task.lambda0 (include/crow/private/rt-main:87)
	at call-w-ctx@(gc-ptr(nat64 future), void) (generated)
	at then@(nat64, void).lambda0.lambda0 (include/crow/future:130)
	at call-w-ctx@(gc-ptr(nat64 future), void) (generated)
	at catch@(out^).lambda0 (include/crow/private/exception-low-level:62)
	at call-w-ctx@((nat64 future, exception) result, void) (generated)
	at catch@((t, exception) result) (include/crow/private/exception-low-level:47)
	at catch@(out^) (include/crow/private/exception-low-level:62)
	at then@(nat64, void).lambda0 (include/crow/future:130)
	at call-w-ctx@(void, void) (generated)
	at invoke-action (include/crow/private/runtime:174)
	at do-task (include/crow/private/runtime:168)
	at thread-function (include/crow/private/runtime:153)
