uncaught exception: FOO
	at bar (test/runnable/fail:9)
	at foo (test/runnable/fail:6)
	at main (test/runnable/fail:3)
	at add-first-task.lambda0 (include/crow/private/rt-main:85)
	at call-w-ctx<gc-ptr(future<nat64>)> (generated)
	at catch<future<out>>.lambda0 (include/crow/private/exception-low-level:94)
	at call-w-ctx<result<future<nat64>, exception>> (generated)
	at catch<result<a, exception>> (include/crow/private/exception-low-level:46)
